<?xml version="1.0"?>
<robot name="READY-5.0" xmlns:xacro="http://www.ros.org/wiki/xacro">
  <xacro:macro name="racer5_080_SE" params="prefix">
    <!-- links: main serial chain -->
    <link name="${prefix}base_link">
      <visual>
        <origin xyz="0 0 -0.365" rpy="0 0 0"/>
        <geometry>
          <mesh filename="meshes/visual/base_link.dae"/>
        </geometry>
      </visual>
      <collision>
        <origin xyz="0 0 -0.365" rpy="0 0 0"/>
        <geometry>
          <mesh filename="meshes/visual/base_link.dae"/>
        </geometry>
      </collision>
    </link>
    <link name="${prefix}link_1">
      <visual>
        <origin xyz="0 0 -0.365" rpy="0 0 0"/>
        <geometry>
          <mesh filename="meshes/visual/link_1.dae"/>
        </geometry>
      </visual>
      <collision>
        <origin xyz="0 0 -0.365" rpy="0 0 0"/>
        <geometry>
          <mesh filename="meshes/visual/link_1.dae"/>
        </geometry>
      </collision>
    </link>
    <link name="${prefix}link_2">
      <visual>
        <origin xyz="0 -0.038 0.195" rpy="0 0 ${-pi/2.0}"/>
        <geometry>
          <mesh filename="meshes/visual/link_2.dae"/>
        </geometry>
      </visual>
      <collision>
        <origin xyz="0 -0.038 0.195" rpy="0 0 ${-pi/2.0}"/>
        <geometry>
          <mesh filename="meshes/visual/link_2.dae"/>
        </geometry>
      </collision>
    </link>
    <link name="${prefix}link_3">
      <visual>
        <origin xyz="0 0 0" rpy="${pi/2.0} ${-pi/2.0} 0"/>
        <geometry>
          <mesh filename="meshes/visual/link_3.dae"/>
        </geometry>
      </visual>
      <collision>
        <origin xyz="0 0 0" rpy="${pi/2.0} ${-pi/2.0} 0"/>
        <geometry>
          <mesh filename="meshes/visual/link_3.dae"/>
        </geometry>
      </collision>
    </link>
    <link name="${prefix}link_4">
      <visual>
        <origin xyz="0.1885 0.1135 0.5195" rpy="0 ${-pi} ${pi/2.0}"/>
        <geometry>
          <mesh filename="meshes/visual/link_4.dae"/>
        </geometry>
      </visual>
      <collision>
        <origin xyz="0.1885 0.1135 0.5195" rpy="0 ${-pi} ${pi/2.0}"/>
        <geometry>
          <mesh filename="meshes/visual/link_4.dae"/>
        </geometry>
      </collision>
    </link>
    <link name="${prefix}link_5">
      <visual>
        <origin xyz="0 0 0" rpy="${-pi/2.0} ${pi/2.0} 0"/>
        <geometry>
          <mesh filename="meshes/visual/link_5.dae"/>
        </geometry>
      </visual>
      <collision>
        <origin xyz="0 0 0" rpy="${-pi/2.0} ${pi/2.0} 0"/>
        <geometry>
          <mesh filename="meshes/visual/link_5.dae"/>
        </geometry>
      </collision>
    </link>
    <link name="${prefix}link_6">
      <visual>
        <origin xyz="0 0 -0.035" rpy="0 0 ${pi/2.0}"/>
        <geometry>
          <mesh filename="meshes/visual/link_6.dae"/>
        </geometry>
      </visual>
      <collision>
        <origin xyz="0 0 -0.035" rpy="0 0 ${pi/2.0}"/>
        <geometry>
          <mesh filename="meshes/visual/link_6.dae"/>
        </geometry>
      </collision>
    </link>

    <!-- joints: main serial chain -->
    <joint name="${prefix}J1" type="revolute">
      <origin xyz="0 0 0" rpy="0 0 0" />
      <parent link="${prefix}base_link" />
      <child link="${prefix}link_1" />
      <axis xyz="0 0 -1" />
      <limit effort="0" lower="${radians(-170.0)}" upper="${radians(170.0)}" velocity="${radians(400.0)}" />
    </joint>
    <joint name="${prefix}J2" type="revolute">
      <origin xyz="0.050 0 0" rpy="0 0 0"/>
      <parent link="${prefix}link_1" />
      <child link="${prefix}link_2" />
      <axis xyz="0 1 0" />
      <limit effort="0" lower="${radians(-85.0)}" upper="${radians(135.0)}" velocity="${radians(360.0)}" />
    </joint>
    <joint name="${prefix}J3" type="revolute">
      <origin xyz="0 0 0.370" rpy="0 0 0"/>
      <parent link="${prefix}link_2" />
      <child link="${prefix}link_3" />
      <axis xyz="0 -1 0" />
      <limit effort="0" lower="${radians(-155.0)}" upper="${radians(90.0)}" velocity="${radians(400.0)}" />
    </joint>
    <joint name="${prefix}J4" type="revolute">
      <origin xyz="-0.050 0 0" rpy="0 0 0"/>
      <parent link="${prefix}link_3"/>
      <child link="${prefix}link_4"/>
      <axis xyz="0 0 -1"/>
      <limit effort="0" lower="${radians(-200.0)}" upper="${radians(200.0)}" velocity="${radians(500.0)}" />
    </joint>
    <joint name="${prefix}J5" type="revolute">
      <origin xyz="0 0 0.38594" rpy="0 0 0"/>
      <parent link="${prefix}link_4"/>
      <child link="${prefix}link_5"/>
      <axis xyz="0 1 0"/>
      <limit effort="0" lower="${radians(-125.0)}" upper="${radians(125.0)}" velocity="${radians(500.0)}" />
    </joint>
    <joint name="${prefix}J6" type="revolute">
      <origin xyz="0 0 0.080" rpy="0 0 0"/>
      <parent link="${prefix}link_5"/>
      <child link="${prefix}link_6"/>
      <axis xyz="0 0 -1"/>
      <limit effort="0" lower="${radians(-2700.0)}" upper="${radians(2700.0)}" velocity="${radians(800.0)}" />
    </joint>

    <link name="${prefix}base" />
    <joint name="${prefix}base_link-base" type="fixed">
      <origin xyz="0 0 0.365" rpy="0 0 0"/>
      <parent link="${prefix}base"/>
      <child link="${prefix}base_link"/>
    </joint>

    <link name="${prefix}tool0" />
    <joint name="${prefix}link_6-tool0" type="fixed">
      <origin xyz="0 0 0" rpy="0 0 0" />
      <parent link="${prefix}link_6" />
      <child link="${prefix}tool0" />
    </joint>
  </xacro:macro>
  <xacro:racer5_080_SE prefix=""/>
</robot>
